Traceback (most recent call last):
  File "/home/jubayer/anaconda3/envs/dsn-template/lib/python3.7/site-packages/jupyter_cache/executors/utils.py", line 56, in single_nb_execution
    record_timing=False,
  File "/home/jubayer/anaconda3/envs/dsn-template/lib/python3.7/site-packages/nbclient/client.py", line 1082, in execute
    return NotebookClient(nb=nb, resources=resources, km=km, **kwargs).execute()
  File "/home/jubayer/anaconda3/envs/dsn-template/lib/python3.7/site-packages/nbclient/util.py", line 74, in wrapped
    return just_run(coro(*args, **kwargs))
  File "/home/jubayer/anaconda3/envs/dsn-template/lib/python3.7/site-packages/nbclient/util.py", line 53, in just_run
    return loop.run_until_complete(coro)
  File "/home/jubayer/anaconda3/envs/dsn-template/lib/python3.7/asyncio/base_events.py", line 587, in run_until_complete
    return future.result()
  File "/home/jubayer/anaconda3/envs/dsn-template/lib/python3.7/site-packages/nbclient/client.py", line 536, in async_execute
    cell, index, execution_count=self.code_cells_executed + 1
  File "/home/jubayer/anaconda3/envs/dsn-template/lib/python3.7/site-packages/nbclient/client.py", line 827, in async_execute_cell
    self._check_raise_for_error(cell, exec_reply)
  File "/home/jubayer/anaconda3/envs/dsn-template/lib/python3.7/site-packages/nbclient/client.py", line 735, in _check_raise_for_error
    raise CellExecutionError.from_cell_and_msg(cell, exec_reply['content'])
nbclient.exceptions.CellExecutionError: An error occurred while executing the following cell:
------------------
s[0] #This won't call s.iloc[0] as one might expect, it generates an error instead
------------------

[0;31m---------------------------------------------------------------------------[0m
[0;31mKeyError[0m                                  Traceback (most recent call last)
[0;32m~/.local/lib/python3.7/site-packages/pandas/core/indexes/base.py[0m in [0;36mget_loc[0;34m(self, key, method, tolerance)[0m
[1;32m   2890[0m             [0;32mtry[0m[0;34m:[0m[0;34m[0m[0;34m[0m[0m
[0;32m-> 2891[0;31m                 [0;32mreturn[0m [0mself[0m[0;34m.[0m[0m_engine[0m[0;34m.[0m[0mget_loc[0m[0;34m([0m[0mcasted_key[0m[0;34m)[0m[0;34m[0m[0;34m[0m[0m
[0m[1;32m   2892[0m             [0;32mexcept[0m [0mKeyError[0m [0;32mas[0m [0merr[0m[0;34m:[0m[0;34m[0m[0;34m[0m[0m

[0;32mpandas/_libs/index.pyx[0m in [0;36mpandas._libs.index.IndexEngine.get_loc[0;34m()[0m

[0;32mpandas/_libs/index.pyx[0m in [0;36mpandas._libs.index.IndexEngine.get_loc[0;34m()[0m

[0;32mpandas/_libs/hashtable_class_helper.pxi[0m in [0;36mpandas._libs.hashtable.Int64HashTable.get_item[0;34m()[0m

[0;32mpandas/_libs/hashtable_class_helper.pxi[0m in [0;36mpandas._libs.hashtable.Int64HashTable.get_item[0;34m()[0m

[0;31mKeyError[0m: 0

The above exception was the direct cause of the following exception:

[0;31mKeyError[0m                                  Traceback (most recent call last)
[0;32m<ipython-input-19-00fa51989f14>[0m in [0;36m<module>[0;34m[0m
[0;32m----> 1[0;31m [0ms[0m[0;34m[[0m[0;36m0[0m[0;34m][0m [0;31m#This won't call s.iloc[0] as one might expect, it generates an error instead[0m[0;34m[0m[0;34m[0m[0m
[0m
[0;32m~/.local/lib/python3.7/site-packages/pandas/core/series.py[0m in [0;36m__getitem__[0;34m(self, key)[0m
[1;32m    880[0m [0;34m[0m[0m
[1;32m    881[0m         [0;32melif[0m [0mkey_is_scalar[0m[0;34m:[0m[0;34m[0m[0;34m[0m[0m
[0;32m--> 882[0;31m             [0;32mreturn[0m [0mself[0m[0;34m.[0m[0m_get_value[0m[0;34m([0m[0mkey[0m[0;34m)[0m[0;34m[0m[0;34m[0m[0m
[0m[1;32m    883[0m [0;34m[0m[0m
[1;32m    884[0m         if (

[0;32m~/.local/lib/python3.7/site-packages/pandas/core/series.py[0m in [0;36m_get_value[0;34m(self, label, takeable)[0m
[1;32m    989[0m [0;34m[0m[0m
[1;32m    990[0m         [0;31m# Similar to Index.get_value, but we do not fall back to positional[0m[0;34m[0m[0;34m[0m[0;34m[0m[0m
[0;32m--> 991[0;31m         [0mloc[0m [0;34m=[0m [0mself[0m[0;34m.[0m[0mindex[0m[0;34m.[0m[0mget_loc[0m[0;34m([0m[0mlabel[0m[0;34m)[0m[0;34m[0m[0;34m[0m[0m
[0m[1;32m    992[0m         [0;32mreturn[0m [0mself[0m[0;34m.[0m[0mindex[0m[0;34m.[0m[0m_get_values_for_loc[0m[0;34m([0m[0mself[0m[0;34m,[0m [0mloc[0m[0;34m,[0m [0mlabel[0m[0;34m)[0m[0;34m[0m[0;34m[0m[0m
[1;32m    993[0m [0;34m[0m[0m

[0;32m~/.local/lib/python3.7/site-packages/pandas/core/indexes/base.py[0m in [0;36mget_loc[0;34m(self, key, method, tolerance)[0m
[1;32m   2891[0m                 [0;32mreturn[0m [0mself[0m[0;34m.[0m[0m_engine[0m[0;34m.[0m[0mget_loc[0m[0;34m([0m[0mcasted_key[0m[0;34m)[0m[0;34m[0m[0;34m[0m[0m
[1;32m   2892[0m             [0;32mexcept[0m [0mKeyError[0m [0;32mas[0m [0merr[0m[0;34m:[0m[0;34m[0m[0;34m[0m[0m
[0;32m-> 2893[0;31m                 [0;32mraise[0m [0mKeyError[0m[0;34m([0m[0mkey[0m[0;34m)[0m [0;32mfrom[0m [0merr[0m[0;34m[0m[0;34m[0m[0m
[0m[1;32m   2894[0m [0;34m[0m[0m
[1;32m   2895[0m         [0;32mif[0m [0mtolerance[0m [0;32mis[0m [0;32mnot[0m [0;32mNone[0m[0;34m:[0m[0;34m[0m[0;34m[0m[0m

[0;31mKeyError[0m: 0
KeyError: 0

